<?xml version="1.0" encoding="utf-8"?>
<!-- This URDF was automatically created by SolidWorks to URDF Exporter! Originally created by Stephen Brawner (brawner@gmail.com) 
     Commit Version: 1.5.1-0-g916b5db  Build Version: 1.5.7152.31018
     For more information, please see http://wiki.ros.org/sw_urdf_exporter -->
<robot
  name="AssemMayar1">
  <link
    name="body">
    <inertial>
      <origin
        xyz="0.194840620518466 -0.0500993762462056 0.189320161381719"
        rpy="0 0 0" />
      <mass
        value="2.07237056978059" />
      <inertia
        ixx="0.022275586264248"
        ixy="-3.65414438500673E-17"
        ixz="-3.10124851857659E-07"
        iyy="0.0394356296418045"
        iyz="8.05166309164701E-17"
        izz="0.0199927039609316" />
    </inertial>
    <visual>
      <origin
        xyz="0 0 0"
        rpy="0 0 0" />
      <geometry>
        <mesh
          filename="package://gp_description/meshes/body.STL" />
      </geometry>
      <material
        name="">
        <color
          rgba="0.752941176470588 0.752941176470588 0.752941176470588 1" />
      </material>
    </visual>
    <collision>
      <origin
        xyz="0 0 0"
        rpy="0 0 0" />
      <geometry>
        <mesh
          filename="package://gp_description/meshes/body.STL" />
      </geometry>
    </collision>
  </link>


  <gazebo reference="body">
    <kp>1000.0</kp>
    <kd>1000.0</kd>
    <mu1>0.5</mu1>
    <mu2>0.5</mu2>
    <material>Gazebo/Red</material>
  </gazebo>



  <link
    name="L1">
    <inertial>
      <origin
        xyz="-0.0373820455585466 0.0255094432171235 -0.0537409197115549"
        rpy="0 0 0" />
      <mass
        value="0.22362780384983" />
      <inertia
        ixx="0.000284899843100605"
        ixy="9.55753209420432E-06"
        ixz="-2.01359883696578E-05"
        iyy="0.000182171941843008"
        iyz="3.15337716827252E-06"
        izz="0.000177023737689543" />
    </inertial>
    <visual>
      <origin
        xyz="0 0 0"
        rpy="0 0 0" />
      <geometry>
        <mesh
          filename="package://gp_description/meshes/L1.STL" />
      </geometry>
      <material
        name="">
        <color
          rgba="0.792156862745098 0.819607843137255 0.933333333333333 1" />
      </material>
    </visual>
    <collision>
      <origin
        xyz="0 0 0"
        rpy="0 0 0" />
      <geometry>
        <mesh
          filename="package://gp_description/meshes/L1.STL" />
      </geometry>
    </collision>
  </link>

  <gazebo reference="L1">
    <kp>1000.0</kp>
    <kd>1000.0</kd>
    <mu1>0.5</mu1>
    <mu2>0.5</mu2>
    <material>Gazebo/Red</material>
  </gazebo>

  <joint
    name="J1"
    type="continuous">
    <origin
      xyz="0.302861435713731 -0.0559999999999969 0"
      rpy="-0.443182805233653 0 0" />
    <parent
      link="body" />
    <child
      link="L1" />
    <axis
      xyz="0 0.428816951098299 -0.903391400474212" />
  </joint>


  <link
    name="L2">
    <inertial>
      <origin
        xyz="0.00777387626964088 0.038418063402477 0.0308199598912289"
        rpy="0 0 0" />
      <mass
        value="0.313444790556129" />
      <inertia
        ixx="0.000521422992112443"
        ixy="-5.47063145118895E-05"
        ixz="1.74818821509954E-07"
        iyy="0.000145415523628238"
        iyz="1.68770209607858E-06"
        izz="0.000639263725889673" />
    </inertial>
    <visual>
      <origin
        xyz="0 0 0"
        rpy="0 0 0" />
      <geometry>
        <mesh
          filename="package://gp_description/meshes/L2.STL" />
      </geometry>
      <material
        name="">
        <color
          rgba="0.752941176470588 0.752941176470588 0.752941176470588 1" />
      </material>
    </visual>
    <collision>
      <origin
        xyz="0 0 0"
        rpy="0 0 0" />
      <geometry>
        <mesh
          filename="package://gp_description/meshes/L2.STL" />
      </geometry>
    </collision>
  </link>


  <gazebo reference="L2">
    <kp>1000.0</kp>
    <kd>1000.0</kd>
    <mu1>0.5</mu1>
    <mu2>0.5</mu2>
    <material>Gazebo/Red</material>
  </gazebo>

  <joint
    name="J2"
    type="continuous">
    <origin
      xyz="0 0.0292429920068749 -0.0616063974052487"
      rpy="-1.57079632679489 0.601703590599477 -1.5707963267949" />
    <parent
      link="L1" />
    <child
      link="L2" />
    <axis
      xyz="0 0 1" />
  </joint>


  <link
    name="L3">
    <inertial>
      <origin
        xyz="-0.0736863305348238 -0.0141955868471295 0.0163596517519616"
        rpy="0 0 0" />
      <mass
        value="0.122683458980112" />
      <inertia
        ixx="1.57929618916735E-05"
        ixy="-1.20926090127091E-05"
        ixz="1.34627846313137E-10"
        iyy="0.000283506470085433"
        iyz="2.57383684682322E-10"
        izz="0.0002930507764425" />
    </inertial>
    <visual>
      <origin
        xyz="0 0 0"
        rpy="0 0 0" />
      <geometry>
        <mesh
          filename="package://gp_description/meshes/L3.STL" />
      </geometry>
      <material
        name="">
        <color
          rgba="0.776470588235294 0.756862745098039 0.737254901960784 1" />
      </material>
    </visual>
    <collision>
      <origin
        xyz="0 0 0"
        rpy="0 0 0" />
      <geometry>
        <mesh
          filename="package://gp_description/meshes/L3.STL" />
      </geometry>
    </collision>
  </link>


  <gazebo reference="L3">
    <kp>1000.0</kp>
    <kd>1000.0</kd>
    <mu1>0.5</mu1>
    <mu2>0.5</mu2>
    <material>Gazebo/Red</material>
  </gazebo>

  <joint
    name="J3"
    type="continuous">
    <origin
      xyz="0.040893 0.24156 0"
      rpy="0 0 -1.8917" />
    <parent
      link="L2" />
    <child
      link="L3" />
    <axis
      xyz="0 0 1" />
  </joint>


  <link
    name="L4">
    <inertial>
      <origin
        xyz="-0.0373820455585462 0.0255094432171238 -0.0537409197115559"
        rpy="0 0 0" />
      <mass
        value="0.22362780384983" />
      <inertia
        ixx="0.000284899843100605"
        ixy="9.55753209420387E-06"
        ixz="-2.0135988369657E-05"
        iyy="0.000182171941843008"
        iyz="3.1533771682728E-06"
        izz="0.000177023737689543" />
    </inertial>
    <visual>
      <origin
        xyz="0 0 0"
        rpy="0 0 0" />
      <geometry>
        <mesh
          filename="package://gp_description/meshes/L4.STL" />
      </geometry>
      <material
        name="">
        <color
          rgba="0.792156862745098 0.819607843137255 0.933333333333333 1" />
      </material>
    </visual>
    <collision>
      <origin
        xyz="0 0 0"
        rpy="0 0 0" />
      <geometry>
        <mesh
          filename="package://gp_description/meshes/L4.STL" />
      </geometry>
    </collision>
  </link>


  <gazebo reference="L4">
    <kp>1000.0</kp>
    <kd>1000.0</kd>
    <mu1>0.5</mu1>
    <mu2>0.5</mu2>
    <material>Gazebo/Red</material>
  </gazebo>


  <joint
    name="J4"
    type="continuous">
    <origin
      xyz="0.08682 -0.056 0"
      rpy="-0.44318 0 3.1416" />
    <parent
      link="body" />
    <child
      link="L4" />
    <axis
      xyz="0 0.42882 -0.90339" />
  </joint>


  <link
    name="L5">
    <inertial>
      <origin
        xyz="0.0325877404089316 -0.0202165479788795 -0.0317703260840108"
        rpy="0 0 0" />
      <mass
        value="0.315382477899423" />
      <inertia
        ixx="0.000226638134274223"
        ixy="0.000162232596269673"
        ixz="-1.43807367338264E-06"
        iyy="0.000441167943892957"
        iyz="7.40878855418634E-07"
        izz="0.00064021937237733" />
    </inertial>
    <visual>
      <origin
        xyz="0 0 0"
        rpy="0 0 0" />
      <geometry>
        <mesh
          filename="package://gp_description/meshes/L5.STL" />
      </geometry>
      <material
        name="">
        <color
          rgba="0.752941176470588 0.752941176470588 0.752941176470588 1" />
      </material>
    </visual>
    <collision>
      <origin
        xyz="0 0 0"
        rpy="0 0 0" />
      <geometry>
        <mesh
          filename="package://gp_description/meshes/L5.STL" />
      </geometry>
    </collision>
  </link>


  <gazebo reference="L5">
    <kp>1000.0</kp>
    <kd>1000.0</kd>
    <mu1>0.5</mu1>
    <mu2>0.5</mu2>
    <material>Gazebo/Red</material>
  </gazebo>

  <joint
    name="J5"
    type="continuous">
    <origin
      xyz="0 0.0292429920068751 -0.0616063974052494"
      rpy="1.57079632679489 1.4999477049949 -1.57079632679491" />
    <parent
      link="L4" />
    <child
      link="L5" />
    <axis
      xyz="0 0 1" />
  </joint>


  <link
    name="L6">
    <inertial>
      <origin
        xyz="-0.0736863305348238 -0.0141955868471312 -0.0156671482486623"
        rpy="0 0 0" />
      <mass
        value="0.122683458980112" />
      <inertia
        ixx="1.57929618916736E-05"
        ixy="-1.20926090127092E-05"
        ixz="1.34627847025919E-10"
        iyy="0.000283506470085433"
        iyz="2.5738368474909E-10"
        izz="0.0002930507764425" />
    </inertial>
    <visual>
      <origin
        xyz="0 0 0"
        rpy="0 0 0" />
      <geometry>
        <mesh
          filename="package://gp_description/meshes/L6.STL" />
      </geometry>
      <material
        name="">
        <color
          rgba="0.776470588235294 0.756862745098039 0.737254901960784 1" />
      </material>
    </visual>
    <collision>
      <origin
        xyz="0 0 0"
        rpy="0 0 0" />
      <geometry>
        <mesh
          filename="package://gp_description/meshes/L6.STL" />
      </geometry>
    </collision>
  </link>


  <gazebo reference="L6">
    <kp>1000.0</kp>
    <kd>1000.0</kd>
    <mu1>0.5</mu1>
    <mu2>0.5</mu2>
    <material>Gazebo/Red</material>
  </gazebo>


  <joint
    name="J6"
    type="continuous">
    <origin
      xyz="0.212224173565451 -0.122416911227435 0"
      rpy="0 0 2.46515967371572" />
    <parent
      link="L5" />
    <child
      link="L6" />
    <axis
      xyz="0 0 1" />
  </joint>


  <link
    name="L7">
    <inertial>
      <origin
        xyz="-0.0373820455585462 0.0378331941064387 -0.0797034441557943"
        rpy="0 0 0" />
      <mass
        value="0.22362780384983" />
      <inertia
        ixx="0.000284899843100605"
        ixy="9.5575320942041E-06"
        ixz="-2.01359883696572E-05"
        iyy="0.000182171941843008"
        iyz="3.1533771682732E-06"
        izz="0.000177023737689543" />
    </inertial>
    <visual>
      <origin
        xyz="0 0 0"
        rpy="0 0 0" />
      <geometry>
        <mesh
          filename="package://gp_description/meshes/L7.STL" />
      </geometry>
      <material
        name="">
        <color
          rgba="0.792156862745098 0.819607843137255 0.933333333333333 1" />
      </material>
    </visual>
    <collision>
      <origin
        xyz="0 0 0"
        rpy="0 0 0" />
      <geometry>
        <mesh
          filename="package://gp_description/meshes/L7.STL" />
      </geometry>
    </collision>
  </link>


  <gazebo reference="L7">
    <kp>1000.0</kp>
    <kd>1000.0</kd>
    <mu1>0.5</mu1>
    <mu2>0.5</mu2>
    <material>Gazebo/Red</material>
  </gazebo>


  <joint
    name="J7"
    type="continuous">
    <origin
      xyz="0.30286 -0.056 0.34726"
      rpy="2.6984 0 0" />
    <parent
      link="body" />
    <child
      link="L7" />
    <axis
      xyz="0 0.42882 -0.90339" />
  </joint>


  <link
    name="L8">
    <inertial>
      <origin
        xyz="0.000655768212772065 -0.0389557544094603 0.0315901559547432"
        rpy="0 0 0" />
      <mass
        value="0.314896891263251" />
      <inertia
        ixx="0.000526858937478396"
        ixy="3.14146874773517E-05"
        ixz="2.003927723706E-07"
        iyy="0.000140536846310859"
        iyz="-1.68442172357604E-06"
        izz="0.000639607496401011" />
    </inertial>
    <visual>
      <origin
        xyz="0 0 0"
        rpy="0 0 0" />
      <geometry>
        <mesh
          filename="package://gp_description/meshes/L8.STL" />
      </geometry>
      <material
        name="">
        <color
          rgba="0.776470588235294 0.756862745098039 0.737254901960784 1" />
      </material>
    </visual>
    <collision>
      <origin
        xyz="0 0 0"
        rpy="0 0 0" />
      <geometry>
        <mesh
          filename="package://gp_description/meshes/L8.STL" />
      </geometry>
    </collision>
  </link>

  <gazebo reference="L8">
    <kp>1000.0</kp>
    <kd>1000.0</kd>
    <mu1>0.5</mu1>
    <mu2>0.5</mu2>
    <material>Gazebo/Red</material>
  </gazebo>


  <joint
    name="J8"
    type="continuous">
    <origin
      xyz="0 0.0415667428961858 -0.087568921849491"
      rpy="-1.5707963267949 0.37950047818827 -1.5707963267949" />
    <parent
      link="L7" />
    <child
      link="L8" />
    <axis
      xyz="0 0 1" />
  </joint>


  <link
    name="L9">
    <inertial>
      <origin
        xyz="-0.0736863305348235 -0.0141955868471295 0.0163596517519628"
        rpy="0 0 0" />
      <mass
        value="0.122683458980112" />
      <inertia
        ixx="1.57929618916734E-05"
        ixy="-1.20926090127092E-05"
        ixz="1.34627846817382E-10"
        iyy="0.000283506470085434"
        iyz="2.57383684714913E-10"
        izz="0.0002930507764425" />
    </inertial>
    <visual>
      <origin
        xyz="0 0 0"
        rpy="0 0 0" />
      <geometry>
        <mesh
          filename="package://gp_description/meshes/L9.STL" />
      </geometry>
      <material
        name="">
        <color
          rgba="0.776470588235294 0.756862745098039 0.737254901960784 1" />
      </material>
    </visual>
    <collision>
      <origin
        xyz="0 0 0"
        rpy="0 0 0" />
      <geometry>
        <mesh
          filename="package://gp_description/meshes/L9.STL" />
      </geometry>
    </collision>
  </link>


  <gazebo reference="L9">
    <kp>1000.0</kp>
    <kd>1000.0</kd>
    <mu1>0.5</mu1>
    <mu2>0.5</mu2>
    <material>Gazebo/Red</material>
  </gazebo>


  <joint
    name="J9"
    type="continuous">
    <origin
      xyz="0.01334749009675 -0.244636147182131 0"
      rpy="0 0 1.47207710099986" />
    <parent
      link="L8" />
    <child
      link="L9" />
    <axis
      xyz="0 0 1" />
  </joint>


  <link
    name="L10">
    <inertial>
      <origin
        xyz="-0.0373820455585462 0.0378331941064387 -0.0797034441557946"
        rpy="0 0 0" />
      <mass
        value="0.22362780384983" />
      <inertia
        ixx="0.000284899843100605"
        ixy="9.55753209420399E-06"
        ixz="-2.01359883696572E-05"
        iyy="0.000182171941843008"
        iyz="3.153377168273E-06"
        izz="0.000177023737689542" />
    </inertial>
    <visual>
      <origin
        xyz="0 0 0"
        rpy="0 0 0" />
      <geometry>
        <mesh
          filename="package://gp_description/meshes/L10.STL" />
      </geometry>
      <material
        name="">
        <color
          rgba="0.792156862745098 0.819607843137255 0.933333333333333 1" />
      </material>
    </visual>
    <collision>
      <origin
        xyz="0 0 0"
        rpy="0 0 0" />
      <geometry>
        <mesh
          filename="package://gp_description/meshes/L10.STL" />
      </geometry>
    </collision>
  </link>

  <gazebo reference="L10">
    <kp>1000.0</kp>
    <kd>1000.0</kd>
    <mu1>0.5</mu1>
    <mu2>0.5</mu2>
    <material>Gazebo/Red</material>
  </gazebo>


  <joint
    name="J10"
    type="continuous">
    <origin
      xyz="0.0868198051533953 -0.0559999999999992 0.347261045400022"
      rpy="2.69840984835614 0 3.14159265358979" />
    <parent
      link="body" />
    <child
      link="L10" />
    <axis
      xyz="0 0.428816951098299 -0.903391400474213" />
  </joint>


  <link
    name="L11">
    <inertial>
      <origin
        xyz="0.0325877404070368 -0.0202165479766175 -0.0317703260833667"
        rpy="0 0 0" />
      <mass
        value="0.315382477915719" />
      <inertia
        ixx="0.000226638134277807"
        ixy="0.000162232596271473"
        ixz="-1.43807367335745E-06"
        iyy="0.000441167943890576"
        iyz="7.40878855913763E-07"
        izz="0.000640219372379125" />
    </inertial>
    <visual>
      <origin
        xyz="0 0 0"
        rpy="0 0 0" />
      <geometry>
        <mesh
          filename="package://gp_description/meshes/L11.STL" />
      </geometry>
      <material
        name="">
        <color
          rgba="0.752941176470588 0.752941176470588 0.752941176470588 1" />
      </material>
    </visual>
    <collision>
      <origin
        xyz="0 0 0"
        rpy="0 0 0" />
      <geometry>
        <mesh
          filename="package://gp_description/meshes/L11.STL" />
      </geometry>
    </collision>
  </link>


  <gazebo reference="L11">
    <kp>1000.0</kp>
    <kd>1000.0</kd>
    <mu1>0.5</mu1>
    <mu2>0.5</mu2>
    <material>Gazebo/Red</material>
  </gazebo>


  <joint
    name="J11"
    type="continuous">
    <origin
      xyz="0 0.0415667428961903 -0.0875689218494886"
      rpy="-1.5707963267949 -1.49994770498817 1.5707963267949" />
    <parent
      link="L10" />
    <child
      link="L11" />
    <axis
      xyz="0 0 1" />
  </joint>


  <link
    name="L12">
    <inertial>
      <origin
        xyz="-0.0736863305348236 -0.0141955868471294 -0.0156671482486612"
        rpy="0 0 0" />
      <mass
        value="0.122683458980112" />
      <inertia
        ixx="1.57929618916736E-05"
        ixy="-1.20926090127093E-05"
        ixz="1.34627847089614E-10"
        iyy="0.000283506470085433"
        iyz="2.57383684743268E-10"
        izz="0.0002930507764425" />
    </inertial>
    <visual>
      <origin
        xyz="0 0 0"
        rpy="0 0 0" />
      <geometry>
        <mesh
          filename="package://gp_description/meshes/L12.STL" />
      </geometry>
      <material
        name="">
        <color
          rgba="0.776470588235294 0.756862745098039 0.737254901960784 1" />
      </material>
    </visual>
    <collision>
      <origin
        xyz="0 0 0"
        rpy="0 0 0" />
      <geometry>
        <mesh
          filename="package://gp_description/meshes/L12.STL" />
      </geometry>
    </collision>
  </link>


  <gazebo reference="L12">
    <kp>1000.0</kp>
    <kd>1000.0</kd>
    <mu1>0.5</mu1>
    <mu2>0.5</mu2>
    <material>Gazebo/Red</material>
  </gazebo>


  <joint
    name="J12"
    type="continuous">
    <origin
      xyz="0.212224173564626 -0.122416911228865 0"
      rpy="0 0 2.46515967370899" />
    <parent
      link="L11" />
    <child
      link="L12" />
    <axis
      xyz="0 0 1" />
  </joint>
</robot>
