<?xml version="1.0" encoding="utf-8"?>
<!-- This URDF was automatically created by SolidWorks to URDF Exporter! Originally created by Stephen Brawner (brawner@gmail.com) 
     Commit Version: 1.5.1-0-g916b5db  Build Version: 1.5.7152.31018
     For more information, please see http://wiki.ros.org/sw_urdf_exporter -->
<robot
  name="cheetah">
  <link
    name="body">
    <inertial>
      <origin
        xyz="0.19284 0.27643 -0.15673"
        rpy="0 0 0" />
      <mass
        value="9.2" />
      <inertia
        ixx="0.040749"
        ixy="1.1879E-06"
        ixz="3.0258E-16"
        iyy="0.018249"
        iyz="2.1739E-14"
        izz="0.054303" />
    </inertial>
    <visual>
      <origin
        xyz="0 0 0"
        rpy="0 0 0" />
      <geometry>
        <mesh
          filename="package://gp_description2/meshes/body.STL" />
      </geometry>
      <material
        name="">
        <color
          rgba="0.75294 0.75294 0.75294 1" />
      </material>
    </visual>
    <collision>
      <origin
        xyz="0 0 0"
        rpy="0 0 0" />
      <geometry>
        <mesh
          filename="package://gp_description2/meshes/body.STL" />
      </geometry>
    </collision>
  </link>

  <gazebo reference="body">
    <kp>1000.0</kp>
    <kd>1000.0</kd>
    <mu1>0.5</mu1>
    <mu2>0.5</mu2>
    <material>Gazebo/Red</material>
  </gazebo>

  <link
    name="L1">
    <inertial>
      <origin
        xyz="-0.012048 -4.7684E-14 0.078769"
        rpy="0 0 0" />
      <mass
        value="0.965" />
      <inertia
        ixx="0.00043238"
        ixy="-1.7926E-18"
        ixz="1.1624E-05"
        iyy="0.00026764"
        iyz="8.7573E-18"
        izz="0.00025388" />
    </inertial>
    <visual>
      <origin
        xyz="0 0 0"
        rpy="0 0 0" />
      <geometry>
        <mesh
          filename="package://gp_description2/meshes/L1.STL" />
      </geometry>
      <material
        name="">
        <color
          rgba="0.79216 0.81961 0.93333 1" />
      </material>
    </visual>
    <collision>
      <origin
        xyz="0 0 0"
        rpy="0 0 0" />
      <geometry>
        <mesh
          filename="package://gp_description2/meshes/L1.STL" />
      </geometry>
    </collision>
  </link>

  <gazebo reference="L1">
    <kp>1000.0</kp>
    <kd>1000.0</kd>
    <mu1>0.5</mu1>
    <mu2>0.5</mu2>
    <material>Gazebo/Red</material>
  </gazebo>

  <joint
    name="J1"
    type="continuous">
    <origin
      xyz="0.0678406204337187 0.505929163431331 -0.145853654698431"
      rpy="1.5707963267949 0 3.14159265358979" />
    <parent
      link="body" />
    <child
      link="L1" />
    <axis
      xyz="0 0 1" />
  </joint>

  <link
    name="L2">
    <inertial>
      <origin
        xyz="0.072029 -0.029298 -0.0089026"
        rpy="0 0 0" />
      <mass
        value="1.1" />
      <inertia
        ixx="0.0015109"
        ixy="-1.8255E-08"
        ixz="4.9324E-08"
        iyy="0.00041062"
        iyz="-0.00030529"
        izz="0.0011913" />
    </inertial>
    <visual>
      <origin
        xyz="0 0 0"
        rpy="0 0 0" />
      <geometry>
        <mesh
          filename="package://gp_description2/meshes/L2.STL" />
      </geometry>
      <material
        name="">
        <color
          rgba="0.79216 0.81961 0.93333 1" />
      </material>
    </visual>
    <collision>
      <origin
        xyz="0 0 0"
        rpy="0 0 0" />
      <geometry>
        <mesh
          filename="package://gp_description2/meshes/L2.STL" />
      </geometry>
    </collision>
  </link>

  <gazebo reference="L2">
    <kp>1000.0</kp>
    <kd>1000.0</kd>
    <mu1>0.5</mu1>
    <mu2>0.5</mu2>
    <material>Gazebo/Red</material>
  </gazebo>

  <joint
    name="J2"
    type="continuous">
    <origin
      xyz="0.00999999999967371 0 0.0846500000000681"
      rpy="-1.92527703542744 0 0" />
    <parent
      link="L1" />
    <child
      link="L2" />
    <axis
      xyz="1 0 0" />
  </joint>

  <link
    name="L3">
    <inertial>
      <origin
        xyz="-0.029913 -0.078375 0.043972"
        rpy="0 0 0" />
      <mass
        value="0.18" />
      <inertia
        ixx="0.00051766"
        ixy="-3.2746E-11"
        ixz="2.1922E-11"
        iyy="0.00020158"
        iyz="0.00023278"
        izz="0.00032484" />
    </inertial>
    <visual>
      <origin
        xyz="0 0 0"
        rpy="0 0 0" />
      <geometry>
        <mesh
          filename="package://gp_description2/meshes/L3.STL" />
      </geometry>
      <material
        name="">
        <color
          rgba="0.79216 0.81961 0.93333 1" />
      </material>
    </visual>
    <collision>
      <origin
        xyz="0 0 0"
        rpy="0 0 0" />
      <geometry>
        <mesh
          filename="package://gp_description2/meshes/L3.STL" />
      </geometry>
    </collision>
  </link>

  <gazebo reference="L3">
    <kp>1000.0</kp>
    <kd>1000.0</kd>
    <mu1>0.5</mu1>
    <mu2>0.5</mu2>
    <material>Gazebo/Red</material>
  </gazebo>

  <joint
    name="J3"
    type="continuous">
    <origin
      xyz="0.0708499999998587 -0.229767581450385 -0.0850403346328576"
      rpy="-2.92377114111487 0 -3.14159265358978" />
    <parent
      link="L2" />
    <child
      link="L3" />
    <axis
      xyz="1 0 0" />
  </joint>

  <link
    name="L4">
    <inertial>
      <origin
        xyz="-0.012048 -8.8818E-16 0.078769"
        rpy="0 0 0" />
      <mass
        value="0.965" />
      <inertia
        ixx="0.00043238"
        ixy="5.0773E-18"
        ixz="1.1624E-05"
        iyy="0.00026764"
        iyz="5.485E-19"
        izz="0.00025388" />
    </inertial>
    <visual>
      <origin
        xyz="0 0 0"
        rpy="0 0 0" />
      <geometry>
        <mesh
          filename="package://gp_description2/meshes/L4.STL" />
      </geometry>
      <material
        name="">
        <color
          rgba="0.79216 0.81961 0.93333 1" />
      </material>
    </visual>
    <collision>
      <origin
        xyz="0 0 0"
        rpy="0 0 0" />
      <geometry>
        <mesh
          filename="package://gp_description2/meshes/L4.STL" />
      </geometry>
    </collision>
  </link>

  <gazebo reference="L4">
    <kp>1000.0</kp>
    <kd>1000.0</kd>
    <mu1>0.5</mu1>
    <mu2>0.5</mu2>
    <material>Gazebo/Red</material>
  </gazebo>

  <joint
    name="J4"
    type="continuous">
    <origin
      xyz="0.317840620433723 0.505929163431131 -0.145853654698437"
      rpy="-1.57079632679551 0 0" />
    <parent
      link="body" />
    <child
      link="L4" />
    <axis
      xyz="0 0 1" />
  </joint>

  <link
    name="L5">
    <inertial>
      <origin
        xyz="0.072029 -0.029298 -0.0089026"
        rpy="0 0 0" />
      <mass
        value="1.1" />
      <inertia
        ixx="0.0015109"
        ixy="-1.8255E-08"
        ixz="4.9324E-08"
        iyy="0.00041062"
        iyz="-0.00030529"
        izz="0.0011913" />
    </inertial>
    <visual>
      <origin
        xyz="0 0 0"
        rpy="0 0 0" />
      <geometry>
        <mesh
          filename="package://gp_description2/meshes/L5.STL" />
      </geometry>
      <material
        name="">
        <color
          rgba="0.79216 0.81961 0.93333 1" />
      </material>
    </visual>
    <collision>
      <origin
        xyz="0 0 0"
        rpy="0 0 0" />
      <geometry>
        <mesh
          filename="package://gp_description2/meshes/L5.STL" />
      </geometry>
    </collision>
  </link>

  <gazebo reference="L5">
    <kp>1000.0</kp>
    <kd>1000.0</kd>
    <mu1>0.5</mu1>
    <mu2>0.5</mu2>
    <material>Gazebo/Red</material>
  </gazebo>

  <joint
    name="J5"
    type="continuous">
    <origin
      xyz="0.00999999999980866 0 0.0846500000000526"
      rpy="-1.92527703542803 0 0" />
    <parent
      link="L4" />
    <child
      link="L5" />
    <axis
      xyz="1 0 0" />
  </joint>

  <link
    name="L6">
    <inertial>
      <origin
        xyz="0.030087 -0.078375 0.043972"
        rpy="0 0 0" />
      <mass
        value="0.18" />
      <inertia
        ixx="0.00051766"
        ixy="-3.2746E-11"
        ixz="2.1922E-11"
        iyy="0.00020158"
        iyz="0.00023278"
        izz="0.00032484" />
    </inertial>
    <visual>
      <origin
        xyz="0 0 0"
        rpy="0 0 0" />
      <geometry>
        <mesh
          filename="package://gp_description2/meshes/L6.STL" />
      </geometry>
      <material
        name="">
        <color
          rgba="0.79216 0.81961 0.93333 1" />
      </material>
    </visual>
    <collision>
      <origin
        xyz="0 0 0"
        rpy="0 0 0" />
      <geometry>
        <mesh
          filename="package://gp_description2/meshes/L6.STL" />
      </geometry>
    </collision>
  </link>

  <gazebo reference="L6">
    <kp>1000.0</kp>
    <kd>1000.0</kd>
    <mu1>0.5</mu1>
    <mu2>0.5</mu2>
    <material>Gazebo/Red</material>
  </gazebo>

  <joint
    name="J6"
    type="continuous">
    <origin
      xyz="0.0708500000002597 -0.229767581450278 -0.0850403346328106"
      rpy="0.926782929741215 0 0" />
    <parent
      link="L5" />
    <child
      link="L6" />
    <axis
      xyz="1 0 0" />
  </joint>

  <link
    name="L7">
    <inertial>
      <origin
        xyz="-0.012048 -2.2204E-16 0.03184"
        rpy="0 0 0" />
      <mass
        value="0.965" />
      <inertia
        ixx="0.00043238"
        ixy="-4.0343E-20"
        ixz="1.1624E-05"
        iyy="0.00026764"
        iyz="6.8191E-20"
        izz="0.00025388" />
    </inertial>
    <visual>
      <origin
        xyz="0 0 0"
        rpy="0 0 0" />
      <geometry>
        <mesh
          filename="package://gp_description2/meshes/L7.STL" />
      </geometry>
      <material
        name="">
        <color
          rgba="0.79216 0.81961 0.93333 1" />
      </material>
    </visual>
    <collision>
      <origin
        xyz="0 0 0"
        rpy="0 0 0" />
      <geometry>
        <mesh
          filename="package://gp_description2/meshes/L7.STL" />
      </geometry>
    </collision>
  </link>

  <gazebo reference="L7">
    <kp>1000.0</kp>
    <kd>1000.0</kd>
    <mu1>0.5</mu1>
    <mu2>0.5</mu2>
    <material>Gazebo/Red</material>
  </gazebo>

  <joint
    name="J7"
    type="continuous">
    <origin
      xyz="0.317840620433344 0 -0.145853654698063"
      rpy="1.5707963267949 0 0" />
    <parent
      link="body" />
    <child
      link="L7" />
    <axis
      xyz="0 0 1" />
  </joint>

  <link
    name="L8">
    <inertial>
      <origin
        xyz="0.072029 -0.029298 -0.0089026"
        rpy="0 0 0" />
      <mass
        value="1.1" />
      <inertia
        ixx="0.0015109"
        ixy="-1.8255E-08"
        ixz="4.9324E-08"
        iyy="0.00041062"
        iyz="-0.00030529"
        izz="0.0011913" />
    </inertial>
    <visual>
      <origin
        xyz="0 0 0"
        rpy="0 0 0" />
      <geometry>
        <mesh
          filename="package://gp_description2/meshes/L8.STL" />
      </geometry>
      <material
        name="">
        <color
          rgba="0.79216 0.81961 0.93333 1" />
      </material>
    </visual>
    <collision>
      <origin
        xyz="0 0 0"
        rpy="0 0 0" />
      <geometry>
        <mesh
          filename="package://gp_description2/meshes/L8.STL" />
      </geometry>
    </collision>
  </link>

  <gazebo reference="L8">
    <kp>1000.0</kp>
    <kd>1000.0</kd>
    <mu1>0.5</mu1>
    <mu2>0.5</mu2>
    <material>Gazebo/Red</material>
  </gazebo>

  <joint
    name="J8"
    type="continuous">
    <origin
      xyz="0.0100000000000001 0 0.0377208365684645"
      rpy="1.21631561816249 0 0" />
    <parent
      link="L7" />
    <child
      link="L8" />
    <axis
      xyz="1 0 0" />
  </joint>

  <link
    name="L9">
    <inertial>
      <origin
        xyz="0.030087 -0.078375 0.043972"
        rpy="0 0 0" />
      <mass
        value="0.18" />
      <inertia
        ixx="0.00051766"
        ixy="-3.2747E-11"
        ixz="2.1923E-11"
        iyy="0.00020158"
        iyz="0.00023278"
        izz="0.00032484" />
    </inertial>
    <visual>
      <origin
        xyz="0 0 0"
        rpy="0 0 0" />
      <geometry>
        <mesh
          filename="package://gp_description2/meshes/L9.STL" />
      </geometry>
      <material
        name="">
        <color
          rgba="0.79216 0.81961 0.93333 1" />
      </material>
    </visual>
    <collision>
      <origin
        xyz="0 0 0"
        rpy="0 0 0" />
      <geometry>
        <mesh
          filename="package://gp_description2/meshes/L9.STL" />
      </geometry>
    </collision>
  </link>

  <gazebo reference="L9">
    <kp>1000.0</kp>
    <kd>1000.0</kd>
    <mu1>0.5</mu1>
    <mu2>0.5</mu2>
    <material>Gazebo/Red</material>
  </gazebo>

  <joint
    name="J9"
    type="continuous">
    <origin
      xyz="0.0708499999999574 -0.229767581450119 -0.0850403346322273"
      rpy="0.926782929739437 0 0" />
    <parent
      link="L8" />
    <child
      link="L9" />
    <axis
      xyz="1 0 0" />
  </joint>

  <link
    name="L10">
    <inertial>
      <origin
        xyz="-0.012048 -1.9124E-14 0.03184"
        rpy="0 0 0" />
      <mass
        value="0.965" />
      <inertia
        ixx="0.00043238"
        ixy="-6.8986E-18"
        ixz="1.1624E-05"
        iyy="0.00026764"
        iyz="8.1696E-18"
        izz="0.00025388" />
    </inertial>
    <visual>
      <origin
        xyz="0 0 0"
        rpy="0 0 0" />
      <geometry>
        <mesh
          filename="package://gp_description2/meshes/L10.STL" />
      </geometry>
      <material
        name="">
        <color
          rgba="0.79216 0.81961 0.93333 1" />
      </material>
    </visual>
    <collision>
      <origin
        xyz="0 0 0"
        rpy="0 0 0" />
      <geometry>
        <mesh
          filename="package://gp_description2/meshes/L10.STL" />
      </geometry>
    </collision>
  </link>

  <gazebo reference="L10">
    <kp>1000.0</kp>
    <kd>1000.0</kd>
    <mu1>0.5</mu1>
    <mu2>0.5</mu2>
    <material>Gazebo/Red</material>
  </gazebo>

  <joint
    name="J10"
    type="continuous">
    <origin
      xyz="0.0678406204333118 0 -0.145853654698131"
      rpy="-1.5707963267949 0 3.14159265358979" />
    <parent
      link="body" />
    <child
      link="L10" />
    <axis
      xyz="0 0 1" />
  </joint>

  <link
    name="L11">
    <inertial>
      <origin
        xyz="0.082029 -0.040813 -0.013165"
        rpy="0 0 0" />
      <mass
        value="1.1" />
      <inertia
        ixx="0.0015109"
        ixy="-1.8255E-08"
        ixz="4.9324E-08"
        iyy="0.00041062"
        iyz="-0.00030529"
        izz="0.0011913" />
    </inertial>
    <visual>
      <origin
        xyz="0 0 0"
        rpy="0 0 0" />
      <geometry>
        <mesh
          filename="package://gp_description2/meshes/L11.STL" />
      </geometry>
      <material
        name="">
        <color
          rgba="0.79216 0.81961 0.93333 1" />
      </material>
    </visual>
    <collision>
      <origin
        xyz="0 0 0"
        rpy="0 0 0" />
      <geometry>
        <mesh
          filename="package://gp_description2/meshes/L11.STL" />
      </geometry>
    </collision>
  </link>

  <gazebo reference="L11">
    <kp>1000.0</kp>
    <kd>1000.0</kd>
    <mu1>0.5</mu1>
    <mu2>0.5</mu2>
    <material>Gazebo/Red</material>
  </gazebo>

  <joint
    name="J11"
    type="continuous">
    <origin
      xyz="0 0 0.05"
      rpy="1.21631561816235 0 0" />
    <parent
      link="L10" />
    <child
      link="L11" />
    <axis
      xyz="1 0 0" />
  </joint>

  <link
    name="L12">
    <inertial>
      <origin
        xyz="-0.029913 -0.078375 0.043972"
        rpy="0 0 0" />
      <mass
        value="0.18" />
      <inertia
        ixx="0.00051766"
        ixy="-3.2748E-11"
        ixz="2.1924E-11"
        iyy="0.00020158"
        iyz="0.00023278"
        izz="0.00032484" />
    </inertial>
    <visual>
      <origin
        xyz="0 0 0"
        rpy="0 0 0" />
      <geometry>
        <mesh
          filename="package://gp_description2/meshes/L12.STL" />
      </geometry>
      <material
        name="">
        <color
          rgba="0.79216 0.81961 0.93333 1" />
      </material>
    </visual>
    <collision>
      <origin
        xyz="0 0 0"
        rpy="0 0 0" />
      <geometry>
        <mesh
          filename="package://gp_description2/meshes/L12.STL" />
      </geometry>
    </collision>
  </link>

  <gazebo reference="L12">
    <kp>1000.0</kp>
    <kd>1000.0</kd>
    <mu1>0.5</mu1>
    <mu2>0.5</mu2>
    <material>Gazebo/Red</material>
  </gazebo>

  <joint
    name="J12"
    type="continuous">
    <origin
      xyz="0.0808499999995903 -0.241283310772285 -0.0893024740908864"
      rpy="-2.92377114111488 0 -3.14159265358978" />
    <parent
      link="L11" />
    <child
      link="L12" />
    <axis
      xyz="1 0 0" />
  </joint>
</robot>
